File: Specimen_RawData_2.csv
Course,"AE321"
Lab Section Number,"12"
Test Group,"C"
Type of Test,"Tensile - Round"
Crosshead Rate,4.00,mm/min
Start Date,10/8/2015 3:14 PM
End Date,10/8/2015 3:16 PM
Material,"1045CR"
Heat treatment,""
Other information,""
Geometry,Circular
Diameter,7.22,mm
Area,40.9415,mm^2
Hardness,0.0
Rockwell Scale,HRB
Grip Diameter (Hardness correction),12.50,mm
Gage Length (Extensometer),25.40,mm
Maximum Load,40540,N
Tensile strain at Maximum Load,0.02261,mm/mm
Tensile strain at Maximum Strain 1,0.07374,mm/mm
Load at Maximum Strain 1,18830,N
Fracture Type and Location,"breaks at around 45 degrees"
Final Diameter,5.32,mm
Notes During Test,""

Time,Extension,Load,Strain 1
(sec),(mm),(N),(mm/mm)
0.00,0.00,9.774,-0.00002
0.50,0.03,739.8,0.00004
1.00,0.07,1457,0.0001298
1.50,0.10,1917,0.0001728
2.00,0.13,2280,0.0002276
2.50,0.17,2582,0.0002587
3.00,0.20,2836,0.0002798
3.50,0.23,3065,0.0003134
4.00,0.27,3309,0.0003494
4.50,0.30,3556,0.0003877
5.00,0.33,3804,0.0004186
5.50,0.37,4056,0.0004484
6.00,0.40,4313,0.0004826
6.50,0.43,4569,0.0005017
7.00,0.47,4825,0.0005434
7.50,0.50,5082,0.0005783
8.00,0.53,5330,0.0006013
8.50,0.57,5567,0.0006377
9.00,0.60,5802,0.0006511
9.50,0.63,6031,0.0006908
10.00,0.67,6267,0.0007176
10.50,0.70,6506,0.0007565
11.00,0.73,6745,0.0007857
11.50,0.77,6991,0.0008222
12.00,0.80,7235,0.0008513
12.50,0.83,7482,0.0008909
13.00,0.87,7731,0.0009238
13.50,0.90,7984,0.0009586
14.00,0.93,8240,0.0009887
14.50,0.97,8497,0.001018
15.00,1.00,8751,0.001053
15.50,1.03,9011,0.001081
16.00,1.07,9275,0.001116
16.50,1.10,9536,0.001139
17.00,1.13,9800,0.001167
17.50,1.17,10070,0.001200
18.00,1.20,10330,0.001229
18.50,1.23,10600,0.001262
19.00,1.27,10870,0.001288
19.50,1.30,11130,0.001320
20.00,1.33,11400,0.001351
20.50,1.37,11670,0.001382
21.00,1.40,11940,0.001418
21.50,1.43,12210,0.001448
22.00,1.47,12480,0.001480
22.50,1.50,12750,0.001513
23.00,1.53,13030,0.001552
23.50,1.57,13300,0.001577
24.00,1.60,13580,0.001607
24.50,1.63,13860,0.001633
25.00,1.67,14140,0.001676
25.50,1.70,14420,0.001711
26.00,1.73,14700,0.001751
26.50,1.77,14980,0.001787
27.00,1.80,15260,0.001814
27.50,1.83,15550,0.001855
28.00,1.87,15830,0.001889
28.50,1.90,16120,0.001928
29.00,1.93,16410,0.001964
29.50,1.97,16690,0.002005
30.00,2.00,16980,0.002050
30.50,2.03,17270,0.002081
31.00,2.07,17560,0.002126
31.50,2.10,17840,0.002163
32.00,2.13,18140,0.002209
32.50,2.17,18430,0.002251
33.00,2.20,18720,0.002299
33.50,2.23,19010,0.002342
34.00,2.27,19300,0.002394
34.50,2.30,19600,0.002437
35.00,2.33,19890,0.002481
35.50,2.37,20180,0.002521
36.00,2.40,20480,0.002579
36.50,2.43,20780,0.002631
37.00,2.47,21080,0.002686
37.50,2.50,21370,0.002735
38.00,2.53,21660,0.002786
38.50,2.57,21960,0.002850
39.00,2.60,22260,0.002910
39.50,2.63,22550,0.002959
40.00,2.67,22850,0.003030
40.50,2.70,23140,0.003087
41.00,2.73,23440,0.003150
41.50,2.77,23740,0.003211
42.00,2.80,24030,0.003276
42.50,2.83,24320,0.003345
43.00,2.87,24620,0.003421
43.50,2.90,24910,0.003486
44.00,2.93,25210,0.003558
44.50,2.97,25500,0.003638
45.00,3.00,25790,0.003712
45.50,3.03,26080,0.003795
46.00,3.07,26370,0.003867
46.50,3.10,26660,0.003939
47.00,3.13,26950,0.004027
47.50,3.17,27240,0.004118
48.00,3.20,27530,0.004207
48.50,3.23,27810,0.004289
49.00,3.27,28090,0.004388
49.50,3.30,28380,0.004475
50.00,3.33,28660,0.004579
50.50,3.37,28950,0.004680
51.00,3.40,29220,0.004786
51.50,3.43,29500,0.004888
52.00,3.47,29780,0.005002
52.50,3.50,30060,0.005116
53.00,3.53,30330,0.005226
53.50,3.57,30600,0.005348
54.00,3.60,30880,0.005462
54.50,3.63,31150,0.005587
55.00,3.67,31420,0.005719
55.50,3.70,31680,0.005850
56.00,3.73,31950,0.005977
56.50,3.77,32210,0.006126
57.00,3.80,32480,0.006265
57.50,3.83,32740,0.006415
58.00,3.87,33000,0.006576
58.50,3.90,33260,0.006722
59.00,3.93,33510,0.006894
59.50,3.97,33770,0.007054
60.00,4.00,34020,0.007230
60.50,4.03,34260,0.007403
61.00,4.07,34510,0.007588
61.50,4.10,34750,0.007770
62.00,4.13,34990,0.007961
62.50,4.17,35220,0.008157
63.00,4.20,35460,0.008368
63.50,4.23,35690,0.008591
64.00,4.27,35910,0.008808
64.50,4.30,36140,0.009028
65.00,4.33,36360,0.009262
65.50,4.37,36570,0.009498
66.00,4.40,36790,0.009743
66.50,4.43,36990,0.009990
67.00,4.47,37200,0.01026
67.50,4.50,37400,0.01052
68.00,4.53,37590,0.01080
68.50,4.57,37780,0.01109
69.00,4.60,37960,0.01138
69.50,4.63,38150,0.01170
70.00,4.67,38320,0.01200
70.50,4.70,38490,0.01232
71.00,4.73,38660,0.01265
71.50,4.77,38810,0.01299
72.00,4.80,38970,0.01335
72.50,4.83,39120,0.01372
73.00,4.87,39260,0.01409
73.50,4.90,39390,0.01448
74.00,4.93,39520,0.01487
74.50,4.97,39640,0.01528
75.00,5.00,39750,0.01571
75.50,5.03,39860,0.01613
76.00,5.07,39950,0.01656
76.50,5.10,40040,0.01703
77.00,5.13,40130,0.01749
77.50,5.17,40200,0.01796
78.00,5.20,40270,0.01843
78.50,5.23,40330,0.01892
79.00,5.27,40380,0.01943
79.50,5.30,40430,0.01993
80.00,5.33,40470,0.02046
80.50,5.37,40500,0.02100
81.00,5.40,40520,0.02153
81.50,5.43,40540,0.02207
82.00,5.47,40540,0.02261
82.50,5.50,40540,0.02317
83.00,5.53,40530,0.02372
83.50,5.57,40520,0.02428
84.00,5.60,40500,0.02482
84.50,5.63,40460,0.02538
85.00,5.67,40420,0.02593
85.50,5.70,40380,0.02648
86.00,5.73,40320,0.02702
86.50,5.77,40260,0.02756
87.00,5.80,40200,0.02809
87.50,5.83,40120,0.02862
88.00,5.87,40050,0.02915
88.50,5.90,39960,0.02968
89.00,5.93,39870,0.03019
89.50,5.97,39780,0.03070
90.00,6.00,39690,0.03121
90.50,6.03,39590,0.03172
91.00,6.07,39490,0.03222
91.50,6.10,39390,0.03271
92.00,6.13,39290,0.03320
92.50,6.17,39190,0.03370
93.00,6.20,39080,0.03418
93.50,6.23,38980,0.03467
94.00,6.27,38870,0.03515
94.50,6.30,38760,0.03563
95.00,6.33,38660,0.03611
95.50,6.37,38550,0.03658
96.00,6.40,38430,0.03704
96.50,6.43,38320,0.03751
97.00,6.47,38210,0.03797
97.50,6.50,38090,0.03843
98.00,6.53,37980,0.03889
98.50,6.57,37860,0.03935
99.00,6.60,37740,0.03980
99.50,6.63,37620,0.04027
100.00,6.67,37510,0.04072
100.50,6.70,37390,0.04117
101.00,6.73,37260,0.04161
101.50,6.77,37140,0.04206
102.00,6.80,37010,0.04251
102.50,6.83,36890,0.04295
103.00,6.87,36760,0.04338
103.50,6.90,36630,0.04381
104.00,6.93,36500,0.04424
104.50,6.97,36370,0.04466
105.00,7.00,36240,0.04507
105.50,7.03,36100,0.04549
106.00,7.07,35960,0.04592
106.50,7.10,35820,0.04633
107.00,7.13,35680,0.04674
107.50,7.17,35530,0.04713
108.00,7.20,35390,0.04752
108.50,7.23,35240,0.04793
109.00,7.27,35090,0.04833
109.50,7.30,34940,0.04873
110.00,7.33,34790,0.04912
110.50,7.37,34630,0.04951
111.00,7.40,34470,0.04989
111.50,7.43,34310,0.05025
112.00,7.47,34150,0.05062
112.50,7.50,33980,0.05097
113.00,7.53,33810,0.05132
113.50,7.57,33640,0.05168
114.00,7.60,33460,0.05203
114.50,7.63,33280,0.05237
115.00,7.67,33100,0.05270
115.50,7.70,32920,0.05303
116.00,7.73,32730,0.05335
116.50,7.77,32540,0.05367
117.00,7.80,32340,0.05401
117.50,7.83,32140,0.05436
118.00,7.87,31920,0.05468
118.50,7.90,31710,0.05499
119.00,7.93,31440,0.05529
119.04,7.94,18830,0.07374