File: Specimen_RawData_3.csv
Course,"ME 330"
Lab Section Number,"02"
Test Group,"A"
Type of Test,"Tensile - Round"
Crosshead Rate,4.00,mm/min
Start Date,9/18/2017 1:12 PM
End Date,9/18/2017 1:14 PM
Material,"6061"
Heat treatment,""
Other information,""
Geometry,Circular
Diameter,7.11,mm
Area,39.7035,mm^2
Hardness,42.8
Rockwell Scale,HRB
Grip Diameter (Hardness correction),12.72,mm
Gage Length (Extensometer),25.40,mm
Maximum Load,11800,N
Tensile strain at Maximum Load,0.1063,mm/mm
Tensile strain at Maximum Strain 1,0.1410,mm/mm
Load at Maximum Strain 1,10970,N
Fracture Type and Location,"Cup Cone, shiny hear breaking point, ductile failure"
Final Diameter,5.10,mm
Notes During Test,""

Time,Extension,Load,Strain 1
(sec),(mm),(N),(mm/mm)
0.00,0.00,29.21,0.00007
0.00,0.00,29.24,0.00006
0.50,0.03,559.3,0.0002446
1.00,0.07,1129,0.0004574
1.50,0.10,1606,0.0006132
2.00,0.13,2026,0.0007739
2.50,0.17,2392,0.0009096
3.00,0.20,2690,0.001014
3.50,0.23,2948,0.001114
4.00,0.27,3196,0.001199
4.50,0.30,3456,0.001305
5.00,0.33,3710,0.001383
5.50,0.37,3963,0.001484
6.00,0.40,4208,0.001575
6.50,0.43,4462,0.001657
7.00,0.47,4715,0.001774
7.50,0.50,4970,0.001855
8.00,0.53,5229,0.001923
8.50,0.57,5491,0.002037
9.00,0.60,5753,0.002122
9.50,0.63,6018,0.002222
10.00,0.67,6283,0.002326
10.50,0.70,6547,0.002408
11.00,0.73,6809,0.002519
11.50,0.77,7073,0.002613
12.00,0.80,7332,0.002711
12.50,0.83,7597,0.002814
13.00,0.87,7854,0.002911
13.50,0.90,8099,0.002999
14.00,0.93,8345,0.003097
14.50,0.97,8577,0.003190
15.00,1.00,8803,0.003289
15.50,1.03,9014,0.003394
16.00,1.07,9203,0.003515
16.50,1.10,9378,0.003680
17.00,1.13,9534,0.003921
17.50,1.17,9653,0.004243
18.00,1.20,9736,0.004665
18.50,1.23,9796,0.005216
19.00,1.27,9842,0.005804
19.50,1.30,9880,0.006463
20.00,1.33,9916,0.007144
20.50,1.37,9944,0.007857
21.00,1.40,9975,0.008581
21.50,1.43,10000,0.009333
22.00,1.47,10030,0.01006
22.50,1.50,10050,0.01079
23.00,1.53,10070,0.01153
23.50,1.57,10100,0.01226
24.00,1.60,10120,0.01298
24.50,1.63,10140,0.01372
25.00,1.67,10170,0.01446
25.50,1.70,10190,0.01516
26.00,1.73,10210,0.01588
26.50,1.77,10230,0.01660
27.00,1.80,10260,0.01732
27.50,1.83,10280,0.01804
28.00,1.87,10300,0.01874
28.50,1.90,10320,0.01947
29.00,1.93,10340,0.02018
29.50,1.97,10360,0.02089
30.00,2.00,10390,0.02160
30.50,2.03,10410,0.02231
31.00,2.07,10430,0.02301
31.50,2.10,10450,0.02371
32.00,2.13,10470,0.02441
32.50,2.17,10490,0.02511
33.00,2.20,10510,0.02582
33.50,2.23,10530,0.02653
34.00,2.27,10550,0.02722
34.50,2.30,10570,0.02790
35.00,2.33,10590,0.02861
35.50,2.37,10620,0.02930
36.00,2.40,10640,0.02999
36.50,2.43,10660,0.03070
37.00,2.47,10670,0.03138
37.50,2.50,10690,0.03206
38.00,2.53,10720,0.03277
38.50,2.57,10730,0.03345
39.00,2.60,10750,0.03414
39.50,2.63,10770,0.03484
40.00,2.67,10790,0.03554
40.50,2.70,10810,0.03624
41.00,2.73,10830,0.03692
41.50,2.77,10850,0.03761
42.00,2.80,10870,0.03831
42.50,2.83,10890,0.03900
43.00,2.87,10900,0.03969
43.50,2.90,10920,0.04039
44.00,2.93,10940,0.04108
44.50,2.97,10960,0.04177
45.00,3.00,10970,0.04246
45.50,3.03,10990,0.04316
46.00,3.07,11010,0.04383
46.50,3.10,11030,0.04453
47.00,3.13,11050,0.04523
47.50,3.17,11060,0.04591
48.00,3.20,11080,0.04662
48.50,3.23,11090,0.04732
49.00,3.27,11110,0.04801
49.50,3.30,11130,0.04869
50.00,3.33,11140,0.04939
50.50,3.37,11160,0.05010
51.00,3.40,11170,0.05078
51.50,3.43,11190,0.05150
52.00,3.47,11200,0.05221
52.50,3.50,11220,0.05289
53.00,3.53,11230,0.05360
53.50,3.57,11250,0.05431
54.00,3.60,11260,0.05501
54.50,3.63,11280,0.05571
55.00,3.67,11290,0.05642
55.50,3.70,11310,0.05712
56.00,3.73,11320,0.05782
56.50,3.77,11340,0.05854
57.00,3.80,11350,0.05925
57.50,3.83,11360,0.05995
58.00,3.87,11370,0.06068
58.50,3.90,11380,0.06139
59.00,3.93,11400,0.06209
59.50,3.97,11410,0.06281
60.00,4.00,11420,0.06353
60.50,4.03,11430,0.06424
61.00,4.07,11450,0.06496
61.50,4.10,11460,0.06568
62.00,4.13,11470,0.06640
62.50,4.17,11480,0.06713
63.00,4.20,11490,0.06784
63.50,4.23,11500,0.06858
64.00,4.27,11520,0.06929
64.50,4.30,11520,0.07001
65.00,4.33,11540,0.07075
65.50,4.37,11540,0.07148
66.00,4.40,11550,0.07221
66.50,4.43,11570,0.07295
67.00,4.47,11570,0.07368
67.50,4.50,11580,0.07440
68.00,4.53,11590,0.07515
68.50,4.57,11600,0.07589
69.00,4.60,11610,0.07662
69.50,4.63,11620,0.07738
70.00,4.67,11630,0.07812
70.50,4.70,11630,0.07886
71.00,4.73,11650,0.07961
71.50,4.77,11650,0.08036
72.00,4.80,11660,0.08112
72.50,4.83,11670,0.08188
73.00,4.87,11670,0.08263
73.50,4.90,11680,0.08338
74.00,4.93,11690,0.08414
74.50,4.97,11690,0.08491
75.00,5.00,11700,0.08568
75.50,5.03,11710,0.08643
76.00,5.07,11710,0.08721
76.50,5.10,11720,0.08800
77.00,5.13,11730,0.08877
77.50,5.17,11730,0.08955
78.00,5.20,11740,0.09034
78.50,5.23,11740,0.09111
79.00,5.27,11740,0.09192
79.50,5.30,11750,0.09270
80.00,5.33,11750,0.09348
80.50,5.37,11760,0.09429
81.00,5.40,11760,0.09508
81.50,5.43,11770,0.09587
82.00,5.47,11770,0.09667
82.50,5.50,11770,0.09745
83.00,5.53,11780,0.09827
83.50,5.57,11780,0.09908
84.00,5.60,11780,0.09987
84.50,5.63,11790,0.1007
85.00,5.67,11790,0.1015
85.50,5.70,11790,0.1023
86.00,5.73,11790,0.1031
86.50,5.77,11790,0.1039
87.00,5.80,11800,0.1047
87.50,5.83,11790,0.1055
88.00,5.87,11800,0.1063
88.50,5.90,11790,0.1071
89.00,5.93,11790,0.1079
89.50,5.97,11800,0.1087
90.00,6.00,11790,0.1095
90.50,6.03,11790,0.1103
91.00,6.07,11790,0.1111
91.50,6.10,11790,0.1119
92.00,6.13,11790,0.1127
92.50,6.17,11780,0.1135
93.00,6.20,11780,0.1143
93.50,6.23,11770,0.1151
94.00,6.27,11770,0.1159
94.50,6.30,11760,0.1166
95.00,6.33,11750,0.1174
95.50,6.37,11740,0.1182
96.00,6.40,11730,0.1189
96.50,6.43,11720,0.1197
97.00,6.47,11710,0.1205
97.50,6.50,11690,0.1213
98.00,6.53,11680,0.1220
98.50,6.57,11660,0.1228
99.00,6.60,11650,0.1235
99.50,6.63,11630,0.1243
100.00,6.67,11610,0.1251
100.50,6.70,11590,0.1258
101.00,6.73,11570,0.1266
101.50,6.77,11550,0.1274
102.00,6.80,11520,0.1281
102.50,6.83,11500,0.1289
103.00,6.87,11470,0.1296
103.50,6.90,11450,0.1304
104.00,6.93,11420,0.1312
104.50,6.97,11390,0.1319
105.00,7.00,11360,0.1327
105.50,7.03,11330,0.1335
106.00,7.07,11300,0.1343
106.50,7.10,11270,0.1350
107.00,7.13,11230,0.1358
107.50,7.17,11200,0.1366
108.00,7.20,11160,0.1374
108.50,7.23,11120,0.1381
109.00,7.27,11090,0.1389
109.50,7.30,11050,0.1396
110.00,7.33,11010,0.1403
110.50,7.36,10970,0.1410
111.00,7.40,10930,0.1128
111.50,7.43,10890,0.1134
112.00,7.47,10840,0.1141
112.50,7.50,10800,0.1147
113.00,7.53,10750,0.1154
113.50,7.57,10710,0.1160
114.00,7.60,10660,0.1167
114.50,7.63,10610,0.1173
115.00,7.67,10570,0.1180
115.50,7.70,10520,0.1186
116.00,7.73,10470,0.1193
116.50,7.77,10420,0.1199
117.00,7.80,10360,0.1206
117.50,7.83,10310,0.1212
118.00,7.87,10260,0.1218
118.50,7.90,10200,0.1225
119.00,7.93,10150,0.1231
119.50,7.97,10090,0.1237
120.00,8.00,10040,0.1242
120.50,8.03,9977,0.1247
121.00,8.07,9916,0.1250
121.50,8.10,9854,0.1240
122.00,8.13,9793,0.1239
122.50,8.17,9730,0.1242
123.00,8.20,9664,0.1245
123.50,8.23,9602,0.1248
124.00,8.27,9533,0.1250
124.50,8.30,9466,0.1253
125.00,8.33,9398,0.1255
125.50,8.37,9328,0.1258
126.00,8.40,9258,0.1261
126.50,8.43,9186,0.1263
127.00,8.47,9111,0.1266
127.50,8.50,9036,0.1268
128.00,8.53,8959,0.1270
128.50,8.57,8878,0.1272
129.00,8.60,8797,0.1274
129.50,8.63,8715,0.1276
130.00,8.67,8625,0.1278
130.50,8.70,8542,0.1280
131.00,8.73,8443,0.1282
131.50,8.77,8336,0.1284
132.00,8.80,8230,0.1286
132.50,8.83,8108,0.1287
133.00,8.87,7825,0.1289